Workbook

Sheet Control Panel
B2: Formatting Guide
B3: What it looks like | C3: What it means
B4: 1000 | C4: Blue font, no shading = hardcoded actual
B5: 1000 | C5: Black font, no shading = formula
C6: Gray shading = deliberately left blank
B7: 1000 | C7: Orange shading = Note attached to cell

Sheet Operating Model
A1: (In Billions)
B2: ='Control Panel'!#REF! -> #REF! | F2: Actual or Forecast | G2: Actual | H2: Actual | I2: Actual | J2: Actual | K2: Forecast | L2: Forecast | M2: Forecast | N2: Forecast | O2: Forecast
A3: Line Item | B3: Assumptions | D3: Notes | F3: Year | G3: 2022 | H3: 2023 | I3: 2024 | J3: 2025 | K3: 2026 | L3: 2027 | M3: 2028 | N3: 2029 | O3: 2030
A4: Income Statement
A5: Revenue
A6: Google Search & other | B6: As the Ai surge excietments slows dowmn the growth rast increas e slows down and starts tod ecrease and taper doiwn to almost pre ai but abit higher as AOI had led to mroi eporple using it | G6: 162.45 | H6: 175.033 | I6: 198.084 | J6: 224.532 | K6: =J6*(1+K7) -> 254.61929 | L6: =K6*(1+L7) -> 287.7198 | M6: =L6*(1+M7) -> 321.38301 | N6: =M6*(1+N7) -> 353.8427 | O6: =N6*(1+O7) -> 384.62701
D7: YoY Growth Rate | H7: =(H6-G6)/G6 -> 0.077457679 | I7: =(I6-H6)/H6 -> 0.13169517 | J7: =(J6-I6)/I6 -> 0.13351911 | K7: 0.134 | L7: 0.13 | M7: 0.117 | N7: 0.101 | O7: 0.087
A8: Youtube ads | B8: "YouTube ads forecast using a constant absolute dollar increase (~$4-4.5bn/year), based on the actual 2024-2025 trend, rather than a constant % growth rate — reflecting a maturing segment without a distinct new growth catalyst (unlike Search's AI-driven acceleration or Cloud's enterprise AI demand). This method naturally implies a decelerating growth rate over the forecast period as the same dollar increase represents a shrinking percentage of an ever-larger base." | G8: 29.243 | H8: 31.51 | I8: 36.147 | J8: 40.367 | K8: 44 | L8: 48 | M8: 52 | N8: 56 | O8: 60
D9: YoY Growth Rate | H9: =(H8-G8)/G8 -> 0.077522826 | I9: =(I8-H8)/H8 -> 0.14715963 | J9: =(J8-I8)/I8 -> 0.11674551 | K9: =(K8-J8)/J8 -> 0.089999257 | L9: =(L8-K8)/K8 -> 0.090909091 | M9: =(M8-L8)/L8 -> 0.083333333 | N9: =(N8-M8)/M8 -> 0.076923077 | O9: =(O8-N8)/N8 -> 0.071428571
A10: Google Network | B10: "Google Network revenue has been in structural decline (-4.48% in 2023, -3.04% in 2024, -1.87% in 2025), and management provided no commentary or forward guidance on this segment in the Q4 2025 earnings call beyond stating the quarterly decline, suggesting it is not a strategic priority. Given the consistent trend of decline decelerating each year and no evidence of a turnaround catalyst, I assumed the rate of decline continues to ease and flattens out near breakeven (-1.0% → -0.5% → -0.3% → +0.1% → +0.1%), reflecting a mature/legacy segment stabilizing rather than reversing into meaningful growth." | G10: 32.78 | H10: 31.312 | I10: 30.359 | J10: 29.792 | K10: =J10*(1+K11) -> 29.49408 | L10: =K10*(1+L11) -> 29.34661 | M10: =L10*(1+M11) -> 29.25857 | N10: =M10*(1+N11) -> 29.25857 | O10: =N10*(1+O11) -> 29.25857
D11: YoY Growth Rate | H11: =(H10-G10)/G10 -> -0.044783405 | I11: =(I10-H10)/H10 -> -0.030435616 | J11: =(J10-I10)/I10 -> -0.018676504 | K11: -0.01 | L11: -0.005 | M11: -0.003 | N11: 0 | O11: 0
A12: Google subscriptions, platforms and devices | B12: "Subscriptions, Platforms and Devices has consistently outgrown Search historically (19.39%, 16.29%, 19.06% vs. Search's 7.75%, 13.17%, 13.35% in 2023-2025), driven by Google One/Gemini premium plan adoption, AI-driven demand for additional storage (larger file sizes from AI-generated content), and subscriber migration from YouTube's ad-supported tier to YouTube Premium/Music. Because this segment's revenue base ($48.0bn in 2025) is much smaller than Search's ($224.5bn), it has more room to sustain high growth before hitting the same base-size constraints — so I tapered it from 19% to 15% over 2026-2030, ending meaningfully above Search's terminal rate to reflect its comparatively smaller scale and stronger recent trend. Note: some of this growth is not fully incremental to the company, as management has noted that YouTube ad-supported users migrating to Premium slightly reduces YouTube Ads revenue while boosting this segment." | G12: 29.055 | H12: 34.688 | I12: 40.34 | J12: 48.03 | K12: =J12*(1+K13) -> 57.1557 | L12: =K12*(1+L13) -> 67.443726 | M12: =L12*(1+M13) -> 78.909159 | N12: =M12*(1+N13) -> 91.534625 | O12: =N12*(1+O13) -> 105.26482
D13: YoY Growth Rate | H13: =(H12-G12)/G12 -> 0.19387369 | I13: =(I12-H12)/H12 -> 0.16293819 | J13: =(J12-I12)/I12 -> 0.19062965 | K13: 0.19 | L13: 0.18 | M13: 0.17 | N13: 0.16 | O13: 0.15
A14: Google Services | G14: =G6+G8+G10+G12 -> 253.528 | H14: =H6+H8+H10+H12 -> 272.543 | I14: =I6+I8+I10+I12 -> 304.93 | J14: =J6+J8+J10+J12 -> 342.721 | K14: =K6+K8+K10+K12 -> 385.26907 | L14: =L6+L8+L10+L12 -> 432.51013 | M14: =M6+M8+M10+M12 -> 481.55074 | N14: =N6+N8+N10+N12 -> 530.63589 | O14: =O6+O8+O10+O12 -> 579.1504
H15: =(H14-G14)/G14 -> 0.075001578 | I15: =(I14-H14)/H14 -> 0.11883262 | J15: =(J14-I14)/I14 -> 0.12393336 | K15: =(K14-J14)/J14 -> 0.12414783 | L15: =(L14-K14)/K14 -> 0.12261836 | M15: =(M14-L14)/L14 -> 0.11338604 | N15: =(N14-M14)/M14 -> 0.10193142 | O15: =(O14-N14)/N14 -> 0.091427114
A16: Google Cloud | B16: Google Cloud revenue growth has accelerated every year historically (25.91% in 2023, 30.65% in 2024, 35.80% in 2025) — the opposite trend of Search or Network. Unlike those segments, Cloud is explicitly supply-constrained rather than demand-constrained: management reported a $240bn backlog (up 55% quarter-over-quarter), stated that customer demand continues to exceed available compute capacity, and confirmed this constraint is expected to persist through 2026. Over half of Alphabet's total 2026 ML compute allocation is being directed to Cloud specifically, backed by the company's $175-185bn 2026 CapEx guidance. Because the binding constraint is capacity rather than customer appetite, I assumed growth continues to climb as new capacity comes online and works through the existing backlog (40% → 43% → 45%), before beginning to ease (45.5% → 44%) as the segment's own revenue base grows large enough (nearing $250-350bn) that even a persistent supply-side tailwind can't fully offset the effect of compounding off an ever-larger base. This is a deliberately bullish assumption reflecting management's explicit conviction and quantified backlog evidence, and results in Cloud approaching Search in absolute size by 2030 — a bold but source-backed call. | G16: 26.28 | H16: 33.088 | I16: 43.229 | J16: 58.705 | K16: =J16*(1+K17) -> 81.0129 | L16: =K16*(1+L17) -> 112.60793 | M16: =L16*(1+M17) -> 156.52502 | N16: =M16*(1+N17) -> 212.87403 | O16: =N16*(1+O17) -> 287.37994
D17: YoY Growth Rate | H17: =(H16-G16)/G16 -> 0.25905632 | I17: =(I16-H16)/H16 -> 0.30648574 | J17: =(J16-I16)/I16 -> 0.35800042 | K17: 0.38 | L17: 0.39 | M17: 0.39 | N17: 0.36 | O17: 0.35
A18: Hedging gains(losses) | G18: 1.96 | H18: 0.236 | I18: 0.211 | J18: -0.127 | K18: 0 | L18: 0 | M18: 0 | N18: 0 | O18: 0
A19: Other Bets | G19: 1.068 | H19: 1.527 | I19: 1.648 | J19: 1.537 | K19: 1.5 | L19: 1.5 | M19: 1.5 | N19: 1.5 | O19: 1.5
A20: Total Revenue | G20: =G14+G16+G18+G19 -> 282.836 | H20: =H14+H16+H18+H19 -> 307.394 | I20: =I14+I16+I18+I19 -> 350.018 | J20: =J14+J16+J18+J19 -> 402.836 | K20: =K14+K16+K18+K19 -> 467.78197 | L20: =L14+L16+L18+L19 -> 546.61806 | M20: =M14+M16+M18+M19 -> 639.57576 | N20: =N14+N16+N18+N19 -> 745.00992 | O20: =O14+O16+O18+O19 -> 868.03034
H21: =(H20-G20)/G20 -> 0.086827702 | I21: =(I20-H20)/H20 -> 0.13866243 | J21: =(J20-I20)/I20 -> 0.15090081 | K21: =(K20-J20)/J20 -> 0.16122186 | L21: =(L20-K20)/K20 -> 0.16853171 | M21: =(M20-L20)/L20 -> 0.1700597 | N21: =(N20-M20)/M20 -> 0.16485015 | O21: =(O20-N20)/N20 -> 0.16512588
A22: Cost of revenues | B22: Cost of Revenue as % of Revenue has improved consistently from 45% (2022) to 40% (2025), reflecting operating leverage as revenue scales faster than underlying costs. However, this trend does not continue unchanged going forward: management stated that 2025's cost of revenue growth (13% YoY) was driven partly by rising depreciation from technical infrastructure deployment, and explicitly guided that depreciation growth will 'accelerate' and 'meaningfully increase' in 2026, reflecting the delayed P&L impact of the 2025 CapEx surge ($91bn) and 2026 guidance ($175-185bn). Because CapEx is capitalized and depreciated over many years rather than expensed immediately, there is a multi-year lag between CapEx spending and its full Cost of Revenue impact — meaning the heaviest pressure from 2025-2026's CapEx wave is expected to hit in 2027-2030, not 2025-2026 itself. I assumed the historical improvement trend continues for one more year (39% in 2026-2027) before reversing as the depreciation lag catches up, rising to 42% by 2030." | G22: 126.203 | H22: 133.332 | I22: 146.306 | J22: 162.535 | K22: =K23*K20 -> 182.43497 | L22: =L23*L20 -> 213.18104 | M22: =M23*M20 -> 252.63243 | N22: =N23*N20 -> 298.00397 | O22: =O23*O20 -> 351.55229
D23: =A22 & "/Revenue" -> Cost of revenues/Revenue | G23: =G22/G20 -> 0.44620557 | H23: =H22/H20 -> 0.43374952 | I23: =I22/I20 -> 0.41799565 | J23: =J22/J20 -> 0.40347685 | K23: 0.39 | L23: 0.39 | M23: 0.395 | N23: 0.4 | O23: 0.405
A24: Gross Profit | G24: =G20-G22 -> 156.633 | H24: =H20-H22 -> 174.062 | I24: =I20-I22 -> 203.712 | J24: =J20-J22 -> 240.301 | K24: =K20-K22 -> 285.347 | L24: =L20-L22 -> 333.43702 | M24: =M20-M22 -> 386.94334 | N24: =N20-N22 -> 447.00595 | O24: =O20-O22 -> 516.47805
A26: R&D | G26: 39.5 | H26: 45.427 | I26: 49.326 | J26: 61.087 | K26: =K27*K20 -> 71.570641 | L26: =L27*L20 -> 84.179182 | M26: =M27*M20 -> 99.134244 | N26: =N27*N20 -> 115.47654 | O26: =O27*O20 -> 134.5447
D27: =A26 & "/Revenue" -> R&D/Revenue | G27: =G26/G20 -> 0.1396569 | H27: =H26/H20 -> 0.14778102 | I27: =I26/I20 -> 0.14092418 | J27: =J26/J20 -> 0.15164236 | K27: 0.153 | L27: 0.154 | M27: 0.155 | N27: 0.155 | O27: 0.155
A28: Sales & marketing | G28: 26.567 | H28: 27.917 | I28: 27.808 | J28: 28.693 | K28: =K29*K20 -> 31.809174 | L28: =L29*L20 -> 35.530174 | M28: =M29*M20 -> 40.293273 | N28: =N29*N20 -> 45.445605 | O28: =O29*O20 -> 52.081821
D29: =A28 & "/Revenue" -> Sales & marketing/Revenue | G29: =G28/G20 -> 0.093930758 | H29: =H28/H20 -> 0.090818298 | I29: =I28/I20 -> 0.079447343 | J29: =J28/J20 -> 0.071227497 | K29: 0.068 | L29: 0.065 | M29: 0.063 | N29: 0.061 | O29: 0.06
A30: General & administrative | G30: 15.724 | H30: 16.425 | I30: 14.188 | J30: 21.482 | K30: =K31*K20 -> 22.219643 | L30: =L31*L20 -> 25.964358 | M30: =M31*M20 -> 30.379849 | N30: =N31*N20 -> 35.387971 | O30: =O31*O20 -> 41.231441
D31: =A30 & "/Revenue" -> General & administrative/Revenue | G31: =G30/G20 -> 0.055594055 | H31: =H30/H20 -> 0.053433053 | I31: =I30/I20 -> 0.040535058 | J31: =J30/J20 -> 0.053326912 | K31: 0.0475 | L31: 0.0475 | M31: 0.0475 | N31: 0.0475 | O31: 0.0475
A32: Operating Expense | G32: 81.791 | H32: 89.769 | I32: 91.322 | J32: 111.262 | K32: =K26+K28+K30 -> 125.59946 | L32: =L26+L28+L30 -> 145.67371 | M32: =M26+M28+M30 -> 169.80737 | N32: =N26+N28+N30 -> 196.31011 | O32: =O26+O28+O30 -> 227.85797
A34: Operating Income | G34: =G24-G32 -> 74.842 | H34: =H24-H32 -> 84.293 | I34: =I24-I32 -> 112.39 | J34: =J24-J32 -> 129.039 | K34: =K24-K32 -> 159.74754 | L34: =L24-L32 -> 187.7633 | M34: =M24-M32 -> 217.13597 | N34: =N24-N32 -> 250.69584 | O34: =O24-O32 -> 288.62009
A35: Operating Margin | G35: =G34/G20 -> 0.26461271 | H35: =H34/H20 -> 0.2742181 | I35: =I34/I20 -> 0.32109777 | J35: =J34/J20 -> 0.32032639 | K35: =K34/K20 -> 0.3415 | L35: =L34/L20 -> 0.3435 | M35: =M34/M20 -> 0.3395 | N35: =N34/N20 -> 0.3365 | O35: =O34/O20 -> 0.3325
A36: Other Income(expense) | D36: "Held at $0 due to high historical volatility and lack of a reliable operating trend" | G36: -3.514 | H36: 1.424 | I36: 7.425 | J36: 29.787 | K36: 0 | L36: 0 | M36: 0 | N36: 0 | O36: 0
A38: Income before Income taxes | G38: =G34+G36 -> 71.328 | H38: =H34+H36 -> 85.717 | I38: =I34+I36 -> 119.815 | J38: =J34+J36 -> 158.826 | K38: =K34+K36 -> 159.74754 | L38: =L34+L36 -> 187.7633 | M38: =M34+M36 -> 217.13597 | N38: =N34+N36 -> 250.69584 | O38: =O34+O36 -> 288.62009
A40: Income Tax Expense | D40: “Effective tax rate held at the historical average of 16% due to no forward guidance" | G40: 11.356 | H40: 11.922 | I40: 19.697 | J40: 26.656 | K40: =K41*K38 -> 25.559607 | L40: =L41*L38 -> 30.042129 | M40: =M41*M38 -> 34.741756 | N40: =N41*N38 -> 40.111334 | O40: =O41*O38 -> 46.179214
G41: =G40/G38 -> 0.15920817 | H41: =H40/H38 -> 0.1390856 | I41: =I40/I38 -> 0.16439511 | J41: =J40/J38 -> 0.16783146 | K41: 0.16 | L41: 0.16 | M41: 0.16 | N41: 0.16 | O41: 0.16
A42: Net Income | G42: =G38-G40 -> 59.972 | H42: =H38-H40 -> 73.795 | I42: =I38-I40 -> 100.118 | J42: =J38-J40 -> 132.17 | K42: =K38-K40 -> 134.18794 | L42: =L38-L40 -> 157.72118 | M42: =M38-M40 -> 182.39422 | N42: =N38-N40 -> 210.5845 | O42: =O38-O40 -> 242.44087
A45: Balance Sheet
A46: Assets
...

Sheet WACC
D1: Commentary
A2: Cost of Equity | B2: Risk free rate | C2: 0.04163 | D2: Return you recieve on a low-risk U.S. Treasury investment
B3: Beta | C3: 1.24 | D3: Measures Alphabet's share price volatility relative to the overall market. A beta of 1.24 indicates higher volatility than the market, 1.
B4: Equity Risk premium | C4: 0.0423 | D4: Additional return investors require for investing in the market rather than risk-free assets
B5: Cost of equity | C5: 0.0941 | D5: RFR+ (Beta*ERP)
A8: Cost of Debt | B8: Cost of Debt (pre-tax) | C8: 0.0466 | D8: Estimated using Alphabet's high credit rating and an approximately 0.5% spread over the risk-free rate.
B9: Cost of Debt (after-tax) | C9: =C8*(1-'Operating Model'!K41) -> 0.039144 | D9: Adjusted for the tax benefit of interest: Pre-tax Cost of Debt × (1 − Tax Rate).
A11: Capital Structure | B11: Share price close | C11: 313.8 | D11: NOT IN BILLIONS
B12: Shares outstanding | C12: 12.228 | D12: in billions (12,228,000,000 shares)
B13: Market Value of Equity (Market Cap) | C13: =C11*C12 -> 3837.1464 | D13: Share price × shares outstanding.
B14: Market value of debt | C14: ='Operating Model'!J57 -> 48.543 | D14: Total debt outstanding.
B15: Total capital | C15: =C13+C14 -> 3885.6894
B17: Weight of equity | C17: 0.9875
B18: Weight of debt | C18: 0.0125
B20: WACC | C20: =(C17*C5)+(C18*C9) -> 0.09341305 | D20: Weighted average of the cost of equity and after-tax cost of debt.
A23: Terminal Value & DCF Bridge | B23: Terminal growth rate | C23: 0.025 | D23: Assumed long-term growth rate of 2.5%, below WACC and consistent with long-term economic growth and inflation expectations.
B24: Normalized temrinal value | C24: =DCF!M10/(WACC!C20-WACC!C23) -> 3623.3456 | D24: Value of the business beyond the explicit forecast period, based on the terminal growth assumption.
B25: PV of normalized terminal value | C25: =C24/((1+C20)^5) -> 2318.4007
B26: Enterprise Value | C26: =C25+SUM(DCF!H11:L11) -> 2376.3758 | D26: Present value of forecast cash flows + present value of terminal value.
B27: Bridge to Equity Value | C27: =C26-'Operating Model'!J57+'Operating Model'!J50 -> 2454.6758 | D27: Enterprise value adjusted for net debt and other relevant balance-sheet items
B28: Implied Share price | C28: =C27/'Operating Model'!J60 -> 200.74222 | D28: Not in Billions

Sheet DCF
A1: (In Billions)
G2: Actual or Forecast | H2: Forecast | I2: Forecast | J2: Forecast | K2: Forecast | L2: Forecast | M2: Terminal
A3: Line Item | B3: Assumptions | F3: Notes | G3: Year | H3: 2026 | I3: 2027 | J3: 2028 | K3: 2029 | L3: 2030 | M3: 2031
A4: DCF Valuation
A5: Free Cash Flow to Firm
A6: NOPAT | B6: Operating Income*(1-Tax Rate) | H6: ='Operating Model'!K34*(1-'Operating Model'!K41) -> 134.18794 | I6: ='Operating Model'!L34*(1-'Operating Model'!L41) -> 157.72118 | J6: ='Operating Model'!M34*(1-'Operating Model'!M41) -> 182.39422 | K6: ='Operating Model'!N34*(1-'Operating Model'!N41) -> 210.5845 | L6: ='Operating Model'!O34*(1-'Operating Model'!O41) -> 242.44087 | M6: =L6*(1+WACC!$C$23) -> 248.5019
A7: D&A | H7: ='Operating Model'!K66 -> 30.6472 | I7: ='Operating Model'!L66 -> 42.90608 | J7: ='Operating Model'!M66 -> 58.78133 | K7: ='Operating Model'!N66 -> 78.179168 | L7: ='Operating Model'!O66 -> 100.85113 | M7: =L7*(1+WACC!$C$23) -> 103.37241
A8: Capex | H8: ='Operating Model'!K77 -> 180 | I8: ='Operating Model'!L77 -> 216 | J8: ='Operating Model'!M77 -> 237.6 | K8: ='Operating Model'!N77 -> 249.48 | L8: ='Operating Model'!O77 -> 254.4696 | M8: =M7 -> 103.37241
A9: Change in Working Capital | H9: ='Operating Model'!K68 -> 0.61491 | I9: ='Operating Model'!L68 -> 0.61183545 | J9: ='Operating Model'!M68 -> 0.60877627 | K9: ='Operating Model'!N68 -> 0.60573239 | L9: ='Operating Model'!O68 -> 0.60270373 | M9: =L9*(1+WACC!$C$23) -> 0.61777132
H10: =H6+H7-H8-H9 -> -15.779775 | I10: =I6+I7-I8-I9 -> -15.98458 | J10: =J6+J7-J8-J9 -> 2.9667699 | K10: =K6+K7-K8-K9 -> 38.677941 | L10: =L6+L7-L8-L9 -> 88.219698 | M10: =M6+M7-M8-M9 -> 247.88413
A11: Present Value of FCFF | H11: =H10/((1+WACC!$C$20)^1) -> -14.431668 | I11: =I10/((1+WACC!$C$20)^2) -> -13.37004 | J11: =J10/((1+WACC!$C$20)^3) -> 2.2695048 | K11: =K10/((1+WACC!$C$20)^4) -> 27.059909 | L11: =L10/((1+WACC!$C$20)^5) -> 56.447447
